[2023-11-19 14:42:41 +0000] [3618] [INFO] Starting gunicorn 21.2.0
[2023-11-19 14:42:41 +0000] [3618] [INFO] Listening at: http://0.0.0.0:8005 (3618)
[2023-11-19 14:42:41 +0000] [3618] [INFO] Using worker: sync
[2023-11-19 14:42:41 +0000] [3637] [INFO] Booting worker with pid: 3637
[2023-11-19 14:42:41 +0000] [3638] [INFO] Booting worker with pid: 3638
[2023-11-19 14:42:41 +0000] [3639] [INFO] Booting worker with pid: 3639
[2023-11-19 14:42:41 +0000] [3640] [INFO] Booting worker with pid: 3640
[2023-11-20 06:13:25,680] ERROR in app: Exception on /visits/ [GET]
Traceback (most recent call last):
  File "/home/basil/web-dev-2023/lab5/ve/lib/python3.8/site-packages/flask/app.py", line 2528, in wsgi_app
    response = self.full_dispatch_request()
  File "/home/basil/web-dev-2023/lab5/ve/lib/python3.8/site-packages/flask/app.py", line 1825, in full_dispatch_request
    rv = self.handle_user_exception(e)
  File "/home/basil/web-dev-2023/lab5/ve/lib/python3.8/site-packages/flask/app.py", line 1823, in full_dispatch_request
    rv = self.dispatch_request()
  File "/home/basil/web-dev-2023/lab5/ve/lib/python3.8/site-packages/flask/app.py", line 1799, in dispatch_request
    return self.ensure_sync(self.view_functions[rule.endpoint])(**view_args)
  File "/home/basil/web-dev-2023/lab5/ve/lib/python3.8/site-packages/flask_login/utils.py", line 285, in decorated_view
    return current_app.login_manager.unauthorized()
  File "/home/basil/web-dev-2023/lab5/ve/lib/python3.8/site-packages/flask_login/login_manager.py", line 196, in unauthorized
    redirect_url = make_login_url(login_view, next_url=request.url)
  File "/home/basil/web-dev-2023/lab5/ve/lib/python3.8/site-packages/flask_login/utils.py", line 120, in login_url
    base = expand_login_view(login_view)
  File "/home/basil/web-dev-2023/lab5/ve/lib/python3.8/site-packages/flask_login/utils.py", line 97, in expand_login_view
    return url_for(login_view)
  File "/home/basil/web-dev-2023/lab5/ve/lib/python3.8/site-packages/flask/helpers.py", line 256, in url_for
    return current_app.url_for(
  File "/home/basil/web-dev-2023/lab5/ve/lib/python3.8/site-packages/flask/app.py", line 2034, in url_for
    return self.handle_url_build_error(error, endpoint, values)
  File "/home/basil/web-dev-2023/lab5/ve/lib/python3.8/site-packages/flask/app.py", line 2023, in url_for
    rv = url_adapter.build(  # type: ignore[union-attr]
  File "/home/basil/web-dev-2023/lab5/ve/lib/python3.8/site-packages/werkzeug/routing/map.py", line 917, in build
    raise BuildError(endpoint, values, method, self)
werkzeug.routing.exceptions.BuildError: Could not build url for endpoint 'login'. Did you mean 'auth.login' instead?
[2023-11-20 06:13:27,103] ERROR in app: Exception on /visits/ [GET]
Traceback (most recent call last):
  File "/home/basil/web-dev-2023/lab5/ve/lib/python3.8/site-packages/flask/app.py", line 2528, in wsgi_app
    response = self.full_dispatch_request()
  File "/home/basil/web-dev-2023/lab5/ve/lib/python3.8/site-packages/flask/app.py", line 1825, in full_dispatch_request
    rv = self.handle_user_exception(e)
  File "/home/basil/web-dev-2023/lab5/ve/lib/python3.8/site-packages/flask/app.py", line 1823, in full_dispatch_request
    rv = self.dispatch_request()
  File "/home/basil/web-dev-2023/lab5/ve/lib/python3.8/site-packages/flask/app.py", line 1799, in dispatch_request
    return self.ensure_sync(self.view_functions[rule.endpoint])(**view_args)
  File "/home/basil/web-dev-2023/lab5/ve/lib/python3.8/site-packages/flask_login/utils.py", line 285, in decorated_view
    return current_app.login_manager.unauthorized()
  File "/home/basil/web-dev-2023/lab5/ve/lib/python3.8/site-packages/flask_login/login_manager.py", line 196, in unauthorized
    redirect_url = make_login_url(login_view, next_url=request.url)
  File "/home/basil/web-dev-2023/lab5/ve/lib/python3.8/site-packages/flask_login/utils.py", line 120, in login_url
    base = expand_login_view(login_view)
  File "/home/basil/web-dev-2023/lab5/ve/lib/python3.8/site-packages/flask_login/utils.py", line 97, in expand_login_view
    return url_for(login_view)
  File "/home/basil/web-dev-2023/lab5/ve/lib/python3.8/site-packages/flask/helpers.py", line 256, in url_for
    return current_app.url_for(
  File "/home/basil/web-dev-2023/lab5/ve/lib/python3.8/site-packages/flask/app.py", line 2034, in url_for
    return self.handle_url_build_error(error, endpoint, values)
  File "/home/basil/web-dev-2023/lab5/ve/lib/python3.8/site-packages/flask/app.py", line 2023, in url_for
    rv = url_adapter.build(  # type: ignore[union-attr]
  File "/home/basil/web-dev-2023/lab5/ve/lib/python3.8/site-packages/werkzeug/routing/map.py", line 917, in build
    raise BuildError(endpoint, values, method, self)
werkzeug.routing.exceptions.BuildError: Could not build url for endpoint 'login'. Did you mean 'auth.login' instead?
[2023-11-20 06:52:54,949] ERROR in app: Exception on /visits/ [GET]
Traceback (most recent call last):
  File "/home/basil/web-dev-2023/lab5/ve/lib/python3.8/site-packages/flask/app.py", line 2528, in wsgi_app
    response = self.full_dispatch_request()
  File "/home/basil/web-dev-2023/lab5/ve/lib/python3.8/site-packages/flask/app.py", line 1825, in full_dispatch_request
    rv = self.handle_user_exception(e)
  File "/home/basil/web-dev-2023/lab5/ve/lib/python3.8/site-packages/flask/app.py", line 1823, in full_dispatch_request
    rv = self.dispatch_request()
  File "/home/basil/web-dev-2023/lab5/ve/lib/python3.8/site-packages/flask/app.py", line 1799, in dispatch_request
    return self.ensure_sync(self.view_functions[rule.endpoint])(**view_args)
  File "/home/basil/web-dev-2023/lab5/ve/lib/python3.8/site-packages/flask_login/utils.py", line 285, in decorated_view
    return current_app.login_manager.unauthorized()
  File "/home/basil/web-dev-2023/lab5/ve/lib/python3.8/site-packages/flask_login/login_manager.py", line 196, in unauthorized
    redirect_url = make_login_url(login_view, next_url=request.url)
  File "/home/basil/web-dev-2023/lab5/ve/lib/python3.8/site-packages/flask_login/utils.py", line 120, in login_url
    base = expand_login_view(login_view)
  File "/home/basil/web-dev-2023/lab5/ve/lib/python3.8/site-packages/flask_login/utils.py", line 97, in expand_login_view
    return url_for(login_view)
  File "/home/basil/web-dev-2023/lab5/ve/lib/python3.8/site-packages/flask/helpers.py", line 256, in url_for
    return current_app.url_for(
  File "/home/basil/web-dev-2023/lab5/ve/lib/python3.8/site-packages/flask/app.py", line 2034, in url_for
    return self.handle_url_build_error(error, endpoint, values)
  File "/home/basil/web-dev-2023/lab5/ve/lib/python3.8/site-packages/flask/app.py", line 2023, in url_for
    rv = url_adapter.build(  # type: ignore[union-attr]
  File "/home/basil/web-dev-2023/lab5/ve/lib/python3.8/site-packages/werkzeug/routing/map.py", line 917, in build
    raise BuildError(endpoint, values, method, self)
werkzeug.routing.exceptions.BuildError: Could not build url for endpoint 'login'. Did you mean 'auth.login' instead?
[2023-11-20 07:04:53,904] ERROR in app: Exception on /visits/ [GET]
Traceback (most recent call last):
  File "/home/basil/web-dev-2023/lab5/ve/lib/python3.8/site-packages/flask/app.py", line 2528, in wsgi_app
    response = self.full_dispatch_request()
  File "/home/basil/web-dev-2023/lab5/ve/lib/python3.8/site-packages/flask/app.py", line 1825, in full_dispatch_request
    rv = self.handle_user_exception(e)
  File "/home/basil/web-dev-2023/lab5/ve/lib/python3.8/site-packages/flask/app.py", line 1823, in full_dispatch_request
    rv = self.dispatch_request()
  File "/home/basil/web-dev-2023/lab5/ve/lib/python3.8/site-packages/flask/app.py", line 1799, in dispatch_request
    return self.ensure_sync(self.view_functions[rule.endpoint])(**view_args)
  File "/home/basil/web-dev-2023/lab5/ve/lib/python3.8/site-packages/flask_login/utils.py", line 285, in decorated_view
    return current_app.login_manager.unauthorized()
  File "/home/basil/web-dev-2023/lab5/ve/lib/python3.8/site-packages/flask_login/login_manager.py", line 196, in unauthorized
    redirect_url = make_login_url(login_view, next_url=request.url)
  File "/home/basil/web-dev-2023/lab5/ve/lib/python3.8/site-packages/flask_login/utils.py", line 120, in login_url
    base = expand_login_view(login_view)
  File "/home/basil/web-dev-2023/lab5/ve/lib/python3.8/site-packages/flask_login/utils.py", line 97, in expand_login_view
    return url_for(login_view)
  File "/home/basil/web-dev-2023/lab5/ve/lib/python3.8/site-packages/flask/helpers.py", line 256, in url_for
    return current_app.url_for(
  File "/home/basil/web-dev-2023/lab5/ve/lib/python3.8/site-packages/flask/app.py", line 2034, in url_for
    return self.handle_url_build_error(error, endpoint, values)
  File "/home/basil/web-dev-2023/lab5/ve/lib/python3.8/site-packages/flask/app.py", line 2023, in url_for
    rv = url_adapter.build(  # type: ignore[union-attr]
  File "/home/basil/web-dev-2023/lab5/ve/lib/python3.8/site-packages/werkzeug/routing/map.py", line 917, in build
    raise BuildError(endpoint, values, method, self)
werkzeug.routing.exceptions.BuildError: Could not build url for endpoint 'login'. Did you mean 'auth.login' instead?
