[2023-11-19 14:42:41 +0000] [3618] [INFO] Starting gunicorn 21.2.0
[2023-11-19 14:42:41 +0000] [3618] [INFO] Listening at: http://0.0.0.0:8005 (3618)
[2023-11-19 14:42:41 +0000] [3618] [INFO] Using worker: sync
[2023-11-19 14:42:41 +0000] [3637] [INFO] Booting worker with pid: 3637
[2023-11-19 14:42:41 +0000] [3638] [INFO] Booting worker with pid: 3638
[2023-11-19 14:42:41 +0000] [3639] [INFO] Booting worker with pid: 3639
[2023-11-19 14:42:41 +0000] [3640] [INFO] Booting worker with pid: 3640
[2023-11-20 06:13:25,680] ERROR in app: Exception on /visits/ [GET]
Traceback (most recent call last):
  File "/home/basil/web-dev-2023/lab5/ve/lib/python3.8/site-packages/flask/app.py", line 2528, in wsgi_app
    response = self.full_dispatch_request()
  File "/home/basil/web-dev-2023/lab5/ve/lib/python3.8/site-packages/flask/app.py", line 1825, in full_dispatch_request
    rv = self.handle_user_exception(e)
  File "/home/basil/web-dev-2023/lab5/ve/lib/python3.8/site-packages/flask/app.py", line 1823, in full_dispatch_request
    rv = self.dispatch_request()
  File "/home/basil/web-dev-2023/lab5/ve/lib/python3.8/site-packages/flask/app.py", line 1799, in dispatch_request
    return self.ensure_sync(self.view_functions[rule.endpoint])(**view_args)
  File "/home/basil/web-dev-2023/lab5/ve/lib/python3.8/site-packages/flask_login/utils.py", line 285, in decorated_view
    return current_app.login_manager.unauthorized()
  File "/home/basil/web-dev-2023/lab5/ve/lib/python3.8/site-packages/flask_login/login_manager.py", line 196, in unauthorized
    redirect_url = make_login_url(login_view, next_url=request.url)
  File "/home/basil/web-dev-2023/lab5/ve/lib/python3.8/site-packages/flask_login/utils.py", line 120, in login_url
    base = expand_login_view(login_view)
  File "/home/basil/web-dev-2023/lab5/ve/lib/python3.8/site-packages/flask_login/utils.py", line 97, in expand_login_view
    return url_for(login_view)
  File "/home/basil/web-dev-2023/lab5/ve/lib/python3.8/site-packages/flask/helpers.py", line 256, in url_for
    return current_app.url_for(
  File "/home/basil/web-dev-2023/lab5/ve/lib/python3.8/site-packages/flask/app.py", line 2034, in url_for
    return self.handle_url_build_error(error, endpoint, values)
  File "/home/basil/web-dev-2023/lab5/ve/lib/python3.8/site-packages/flask/app.py", line 2023, in url_for
    rv = url_adapter.build(  # type: ignore[union-attr]
  File "/home/basil/web-dev-2023/lab5/ve/lib/python3.8/site-packages/werkzeug/routing/map.py", line 917, in build
    raise BuildError(endpoint, values, method, self)
werkzeug.routing.exceptions.BuildError: Could not build url for endpoint 'login'. Did you mean 'auth.login' instead?
[2023-11-20 06:13:27,103] ERROR in app: Exception on /visits/ [GET]
Traceback (most recent call last):
  File "/home/basil/web-dev-2023/lab5/ve/lib/python3.8/site-packages/flask/app.py", line 2528, in wsgi_app
    response = self.full_dispatch_request()
  File "/home/basil/web-dev-2023/lab5/ve/lib/python3.8/site-packages/flask/app.py", line 1825, in full_dispatch_request
    rv = self.handle_user_exception(e)
  File "/home/basil/web-dev-2023/lab5/ve/lib/python3.8/site-packages/flask/app.py", line 1823, in full_dispatch_request
    rv = self.dispatch_request()
  File "/home/basil/web-dev-2023/lab5/ve/lib/python3.8/site-packages/flask/app.py", line 1799, in dispatch_request
    return self.ensure_sync(self.view_functions[rule.endpoint])(**view_args)
  File "/home/basil/web-dev-2023/lab5/ve/lib/python3.8/site-packages/flask_login/utils.py", line 285, in decorated_view
    return current_app.login_manager.unauthorized()
  File "/home/basil/web-dev-2023/lab5/ve/lib/python3.8/site-packages/flask_login/login_manager.py", line 196, in unauthorized
    redirect_url = make_login_url(login_view, next_url=request.url)
  File "/home/basil/web-dev-2023/lab5/ve/lib/python3.8/site-packages/flask_login/utils.py", line 120, in login_url
    base = expand_login_view(login_view)
  File "/home/basil/web-dev-2023/lab5/ve/lib/python3.8/site-packages/flask_login/utils.py", line 97, in expand_login_view
    return url_for(login_view)
  File "/home/basil/web-dev-2023/lab5/ve/lib/python3.8/site-packages/flask/helpers.py", line 256, in url_for
    return current_app.url_for(
  File "/home/basil/web-dev-2023/lab5/ve/lib/python3.8/site-packages/flask/app.py", line 2034, in url_for
    return self.handle_url_build_error(error, endpoint, values)
  File "/home/basil/web-dev-2023/lab5/ve/lib/python3.8/site-packages/flask/app.py", line 2023, in url_for
    rv = url_adapter.build(  # type: ignore[union-attr]
  File "/home/basil/web-dev-2023/lab5/ve/lib/python3.8/site-packages/werkzeug/routing/map.py", line 917, in build
    raise BuildError(endpoint, values, method, self)
werkzeug.routing.exceptions.BuildError: Could not build url for endpoint 'login'. Did you mean 'auth.login' instead?
[2023-11-20 06:52:54,949] ERROR in app: Exception on /visits/ [GET]
Traceback (most recent call last):
  File "/home/basil/web-dev-2023/lab5/ve/lib/python3.8/site-packages/flask/app.py", line 2528, in wsgi_app
    response = self.full_dispatch_request()
  File "/home/basil/web-dev-2023/lab5/ve/lib/python3.8/site-packages/flask/app.py", line 1825, in full_dispatch_request
    rv = self.handle_user_exception(e)
  File "/home/basil/web-dev-2023/lab5/ve/lib/python3.8/site-packages/flask/app.py", line 1823, in full_dispatch_request
    rv = self.dispatch_request()
  File "/home/basil/web-dev-2023/lab5/ve/lib/python3.8/site-packages/flask/app.py", line 1799, in dispatch_request
    return self.ensure_sync(self.view_functions[rule.endpoint])(**view_args)
  File "/home/basil/web-dev-2023/lab5/ve/lib/python3.8/site-packages/flask_login/utils.py", line 285, in decorated_view
    return current_app.login_manager.unauthorized()
  File "/home/basil/web-dev-2023/lab5/ve/lib/python3.8/site-packages/flask_login/login_manager.py", line 196, in unauthorized
    redirect_url = make_login_url(login_view, next_url=request.url)
  File "/home/basil/web-dev-2023/lab5/ve/lib/python3.8/site-packages/flask_login/utils.py", line 120, in login_url
    base = expand_login_view(login_view)
  File "/home/basil/web-dev-2023/lab5/ve/lib/python3.8/site-packages/flask_login/utils.py", line 97, in expand_login_view
    return url_for(login_view)
  File "/home/basil/web-dev-2023/lab5/ve/lib/python3.8/site-packages/flask/helpers.py", line 256, in url_for
    return current_app.url_for(
  File "/home/basil/web-dev-2023/lab5/ve/lib/python3.8/site-packages/flask/app.py", line 2034, in url_for
    return self.handle_url_build_error(error, endpoint, values)
  File "/home/basil/web-dev-2023/lab5/ve/lib/python3.8/site-packages/flask/app.py", line 2023, in url_for
    rv = url_adapter.build(  # type: ignore[union-attr]
  File "/home/basil/web-dev-2023/lab5/ve/lib/python3.8/site-packages/werkzeug/routing/map.py", line 917, in build
    raise BuildError(endpoint, values, method, self)
werkzeug.routing.exceptions.BuildError: Could not build url for endpoint 'login'. Did you mean 'auth.login' instead?
[2023-11-20 07:04:53,904] ERROR in app: Exception on /visits/ [GET]
Traceback (most recent call last):
  File "/home/basil/web-dev-2023/lab5/ve/lib/python3.8/site-packages/flask/app.py", line 2528, in wsgi_app
    response = self.full_dispatch_request()
  File "/home/basil/web-dev-2023/lab5/ve/lib/python3.8/site-packages/flask/app.py", line 1825, in full_dispatch_request
    rv = self.handle_user_exception(e)
  File "/home/basil/web-dev-2023/lab5/ve/lib/python3.8/site-packages/flask/app.py", line 1823, in full_dispatch_request
    rv = self.dispatch_request()
  File "/home/basil/web-dev-2023/lab5/ve/lib/python3.8/site-packages/flask/app.py", line 1799, in dispatch_request
    return self.ensure_sync(self.view_functions[rule.endpoint])(**view_args)
  File "/home/basil/web-dev-2023/lab5/ve/lib/python3.8/site-packages/flask_login/utils.py", line 285, in decorated_view
    return current_app.login_manager.unauthorized()
  File "/home/basil/web-dev-2023/lab5/ve/lib/python3.8/site-packages/flask_login/login_manager.py", line 196, in unauthorized
    redirect_url = make_login_url(login_view, next_url=request.url)
  File "/home/basil/web-dev-2023/lab5/ve/lib/python3.8/site-packages/flask_login/utils.py", line 120, in login_url
    base = expand_login_view(login_view)
  File "/home/basil/web-dev-2023/lab5/ve/lib/python3.8/site-packages/flask_login/utils.py", line 97, in expand_login_view
    return url_for(login_view)
  File "/home/basil/web-dev-2023/lab5/ve/lib/python3.8/site-packages/flask/helpers.py", line 256, in url_for
    return current_app.url_for(
  File "/home/basil/web-dev-2023/lab5/ve/lib/python3.8/site-packages/flask/app.py", line 2034, in url_for
    return self.handle_url_build_error(error, endpoint, values)
  File "/home/basil/web-dev-2023/lab5/ve/lib/python3.8/site-packages/flask/app.py", line 2023, in url_for
    rv = url_adapter.build(  # type: ignore[union-attr]
  File "/home/basil/web-dev-2023/lab5/ve/lib/python3.8/site-packages/werkzeug/routing/map.py", line 917, in build
    raise BuildError(endpoint, values, method, self)
werkzeug.routing.exceptions.BuildError: Could not build url for endpoint 'login'. Did you mean 'auth.login' instead?
[2023-11-20 09:38:46 +0000] [3618] [ERROR] Worker (pid:3640) was sent SIGHUP!
--- Logging error ---
Traceback (most recent call last):
  File "/usr/lib/python3.8/logging/__init__.py", line 1089, in emit
    self.flush()
  File "/usr/lib/python3.8/logging/__init__.py", line 1069, in flush
    self.stream.flush()
RuntimeError: reentrant call inside <_io.BufferedWriter name='<stderr>'>

During handling of the above exception, another exception occurred:

Traceback (most recent call last):
  File "/usr/lib/python3.8/logging/__init__.py", line 1089, in emit
    self.flush()
  File "/usr/lib/python3.8/logging/__init__.py", line 1069, in flush
    self.stream.flush()
RuntimeError: reentrant call inside <_io.BufferedWriter name='<stderr>'>
Call stack:
  File "/home/basil/web-dev-2023/lab5/ve/bin/gunicorn", line 8, in <module>
    sys.exit(run())
  File "/home/basil/web-dev-2023/lab5/ve/lib/python3.8/site-packages/gunicorn/app/wsgiapp.py", line 67, in run
    WSGIApplication("%(prog)s [OPTIONS] [APP_MODULE]").run()
  File "/home/basil/web-dev-2023/lab5/ve/lib/python3.8/site-packages/gunicorn/app/base.py", line 236, in run
    super().run()
  File "/home/basil/web-dev-2023/lab5/ve/lib/python3.8/site-packages/gunicorn/app/base.py", line 72, in run
    Arbiter(self).run()
  File "/home/basil/web-dev-2023/lab5/ve/lib/python3.8/site-packages/gunicorn/arbiter.py", line 209, in run
    self.sleep()
  File "/home/basil/web-dev-2023/lab5/ve/lib/python3.8/site-packages/gunicorn/arbiter.py", line 360, in sleep
    ready = select.select([self.PIPE[0]], [], [], 1.0)
  File "/home/basil/web-dev-2023/lab5/ve/lib/python3.8/site-packages/gunicorn/arbiter.py", line 242, in handle_chld
    self.reap_workers()
  File "/home/basil/web-dev-2023/lab5/ve/lib/python3.8/site-packages/gunicorn/arbiter.py", line 554, in reap_workers
    self.log.error(msg)
  File "/home/basil/web-dev-2023/lab5/ve/lib/python3.8/site-packages/gunicorn/glogging.py", line 272, in error
    self.error_log.error(msg, *args, **kwargs)
  File "/usr/lib/python3.8/logging/__init__.py", line 1475, in error
    self._log(ERROR, msg, args, **kwargs)
  File "/usr/lib/python3.8/logging/__init__.py", line 1589, in _log
    self.handle(record)
  File "/usr/lib/python3.8/logging/__init__.py", line 1599, in handle
    self.callHandlers(record)
  File "/usr/lib/python3.8/logging/__init__.py", line 1661, in callHandlers
    hdlr.handle(record)
  File "/usr/lib/python3.8/logging/__init__.py", line 954, in handle
    self.emit(record)
  File "/usr/lib/python3.8/logging/__init__.py", line 1089, in emit
    self.flush()
  File "/usr/lib/python3.8/logging/__init__.py", line 1069, in flush
    self.stream.flush()
  File "/home/basil/web-dev-2023/lab5/ve/lib/python3.8/site-packages/gunicorn/arbiter.py", line 242, in handle_chld
    self.reap_workers()
  File "/home/basil/web-dev-2023/lab5/ve/lib/python3.8/site-packages/gunicorn/arbiter.py", line 554, in reap_workers
    self.log.error(msg)
  File "/home/basil/web-dev-2023/lab5/ve/lib/python3.8/site-packages/gunicorn/glogging.py", line 272, in error
    self.error_log.error(msg, *args, **kwargs)
  File "/usr/lib/python3.8/logging/__init__.py", line 1475, in error
    self._log(ERROR, msg, args, **kwargs)
  File "/usr/lib/python3.8/logging/__init__.py", line 1589, in _log
    self.handle(record)
  File "/usr/lib/python3.8/logging/__init__.py", line 1599, in handle
    self.callHandlers(record)
  File "/usr/lib/python3.8/logging/__init__.py", line 1661, in callHandlers
    hdlr.handle(record)
  File "/usr/lib/python3.8/logging/__init__.py", line 954, in handle
    self.emit(record)
  File "/usr/lib/python3.8/logging/__init__.py", line 1093, in emit
    self.handleError(record)
  File "/usr/lib/python3.8/logging/__init__.py", line 1007, in handleError
    traceback.print_exception(t, v, tb, None, sys.stderr)
  File "/usr/lib/python3.8/traceback.py", line 103, in print_exception
    for line in TracebackException(
  File "/usr/lib/python3.8/traceback.py", line 508, in __init__
    self.stack = StackSummary.extract(
  File "/usr/lib/python3.8/traceback.py", line 366, in extract
    f.line
  File "/usr/lib/python3.8/traceback.py", line 288, in line
    self._line = linecache.getline(self.filename, self.lineno).strip()
  File "/usr/lib/python3.8/linecache.py", line 16, in getline
    lines = getlines(filename, module_globals)
  File "/usr/lib/python3.8/linecache.py", line 47, in getlines
    return updatecache(filename, module_globals)
  File "/usr/lib/python3.8/linecache.py", line 136, in updatecache
    with tokenize.open(fullname) as fp:
  File "/usr/lib/python3.8/tokenize.py", line 394, in open
    encoding, lines = detect_encoding(buffer.readline)
  File "/usr/lib/python3.8/tokenize.py", line 363, in detect_encoding
    first = read_or_stop()
  File "/usr/lib/python3.8/tokenize.py", line 321, in read_or_stop
    return readline()
  File "/home/basil/web-dev-2023/lab5/ve/lib/python3.8/site-packages/gunicorn/arbiter.py", line 242, in handle_chld
    self.reap_workers()
  File "/home/basil/web-dev-2023/lab5/ve/lib/python3.8/site-packages/gunicorn/arbiter.py", line 554, in reap_workers
    self.log.error(msg)
  File "/home/basil/web-dev-2023/lab5/ve/lib/python3.8/site-packages/gunicorn/glogging.py", line 272, in error
    self.error_log.error(msg, *args, **kwargs)
Message: 'Worker (pid:3639) was sent SIGHUP!'
Arguments: ()
Traceback (most recent call last):
  File "/usr/lib/python3.8/logging/__init__.py", line 1089, in emit
    self.flush()
  File "/usr/lib/python3.8/logging/__init__.py", line 1069, in flush
    self.stream.flush()
RuntimeError: reentrant call inside <_io.BufferedWriter name='<stderr>'>
Call stack:
  File "/home/basil/web-dev-2023/lab5/ve/bin/gunicorn", line 8, in <module>
    sys.exit(run())
  File "/home/basil/web-dev-2023/lab5/ve/lib/python3.8/site-packages/gunicorn/app/wsgiapp.py", line 67, in run
    WSGIApplication("%(prog)s [OPTIONS] [APP_MODULE]").run()
  File "/home/basil/web-dev-2023/lab5/ve/lib/python3.8/site-packages/gunicorn/app/base.py", line 236, in run
    super().run()
  File "/home/basil/web-dev-2023/lab5/ve/lib/python3.8/site-packages/gunicorn/app/base.py", line 72, in run
    Arbiter(self).run()
  File "/home/basil/web-dev-2023/lab5/ve/lib/python3.8/site-packages/gunicorn/arbiter.py", line 209, in run
    self.sleep()
  File "/home/basil/web-dev-2023/lab5/ve/lib/python3.8/site-packages/gunicorn/arbiter.py", line 360, in sleep
    ready = select.select([self.PIPE[0]], [], [], 1.0)
  File "/home/basil/web-dev-2023/lab5/ve/lib/python3.8/site-packages/gunicorn/arbiter.py", line 242, in handle_chld
    self.reap_workers()
  File "/home/basil/web-dev-2023/lab5/ve/lib/python3.8/site-packages/gunicorn/arbiter.py", line 554, in reap_workers
    self.log.error(msg)
  File "/home/basil/web-dev-2023/lab5/ve/lib/python3.8/site-packages/gunicorn/glogging.py", line 272, in error
    self.error_log.error(msg, *args, **kwargs)
  File "/usr/lib/python3.8/logging/__init__.py", line 1475, in error
    self._log(ERROR, msg, args, **kwargs)
  File "/usr/lib/python3.8/logging/__init__.py", line 1589, in _log
    self.handle(record)
  File "/usr/lib/python3.8/logging/__init__.py", line 1599, in handle
    self.callHandlers(record)
  File "/usr/lib/python3.8/logging/__init__.py", line 1661, in callHandlers
    hdlr.handle(record)
  File "/usr/lib/python3.8/logging/__init__.py", line 954, in handle
    self.emit(record)
  File "/usr/lib/python3.8/logging/__init__.py", line 1089, in emit
    self.flush()
  File "/usr/lib/python3.8/logging/__init__.py", line 1069, in flush
    self.stream.flush()
  File "/home/basil/web-dev-2023/lab5/ve/lib/python3.8/site-packages/gunicorn/arbiter.py", line 242, in handle_chld
    self.reap_workers()
  File "/home/basil/web-dev-2023/lab5/ve/lib/python3.8/site-packages/gunicorn/arbiter.py", line 554, in reap_workers
    self.log.error(msg)
  File "/home/basil/web-dev-2023/lab5/ve/lib/python3.8/site-packages/gunicorn/glogging.py", line 272, in error
    self.error_log.error(msg, *args, **kwargs)
Message: 'Worker (pid:3637) was sent SIGHUP!'
Arguments: ()
[2023-11-20 09:38:46 +0000] [17266] [INFO] Booting worker with pid: 17266
--- Logging error ---
Traceback (most recent call last):
  File "/usr/lib/python3.8/logging/__init__.py", line 1089, in emit
    self.flush()
  File "/usr/lib/python3.8/logging/__init__.py", line 1069, in flush
    self.stream.flush()
RuntimeError: reentrant call inside <_io.BufferedWriter name='<stderr>'>

During handling of the above exception, another exception occurred:

Traceback (most recent call last):
  File "/usr/lib/python3.8/logging/__init__.py", line 1089, in emit
    self.flush()
  File "/usr/lib/python3.8/logging/__init__.py", line 1069, in flush
    self.stream.flush()
RuntimeError: reentrant call inside <_io.BufferedWriter name='<stderr>'>
Call stack:
  File "/home/basil/web-dev-2023/lab5/ve/bin/gunicorn", line 8, in <module>
    sys.exit(run())
  File "/home/basil/web-dev-2023/lab5/ve/lib/python3.8/site-packages/gunicorn/app/wsgiapp.py", line 67, in run
    WSGIApplication("%(prog)s [OPTIONS] [APP_MODULE]").run()
  File "/home/basil/web-dev-2023/lab5/ve/lib/python3.8/site-packages/gunicorn/app/base.py", line 236, in run
    super().run()
  File "/home/basil/web-dev-2023/lab5/ve/lib/python3.8/site-packages/gunicorn/app/base.py", line 72, in run
    Arbiter(self).run()
  File "/home/basil/web-dev-2023/lab5/ve/lib/python3.8/site-packages/gunicorn/arbiter.py", line 209, in run
    self.sleep()
  File "/home/basil/web-dev-2023/lab5/ve/lib/python3.8/site-packages/gunicorn/arbiter.py", line 360, in sleep
    ready = select.select([self.PIPE[0]], [], [], 1.0)
  File "/home/basil/web-dev-2023/lab5/ve/lib/python3.8/site-packages/gunicorn/arbiter.py", line 242, in handle_chld
    self.reap_workers()
  File "/home/basil/web-dev-2023/lab5/ve/lib/python3.8/site-packages/gunicorn/arbiter.py", line 554, in reap_workers
    self.log.error(msg)
  File "/home/basil/web-dev-2023/lab5/ve/lib/python3.8/site-packages/gunicorn/glogging.py", line 272, in error
    self.error_log.error(msg, *args, **kwargs)
  File "/usr/lib/python3.8/logging/__init__.py", line 1475, in error
    self._log(ERROR, msg, args, **kwargs)
  File "/usr/lib/python3.8/logging/__init__.py", line 1589, in _log
    self.handle(record)
  File "/usr/lib/python3.8/logging/__init__.py", line 1599, in handle
    self.callHandlers(record)
  File "/usr/lib/python3.8/logging/__init__.py", line 1661, in callHandlers
    hdlr.handle(record)
  File "/usr/lib/python3.8/logging/__init__.py", line 954, in handle
    self.emit(record)
  File "/usr/lib/python3.8/logging/__init__.py", line 1089, in emit
    self.flush()
  File "/usr/lib/python3.8/logging/__init__.py", line 1069, in flush
    self.stream.flush()
  File "/home/basil/web-dev-2023/lab5/ve/lib/python3.8/site-packages/gunicorn/arbiter.py", line 242, in handle_chld
    self.reap_workers()
  File "/home/basil/web-dev-2023/lab5/ve/lib/python3.8/site-packages/gunicorn/arbiter.py", line 554, in reap_workers
    self.log.error(msg)
  File "/home/basil/web-dev-2023/lab5/ve/lib/python3.8/site-packages/gunicorn/glogging.py", line 272, in error
    self.error_log.error(msg, *args, **kwargs)
  File "/usr/lib/python3.8/logging/__init__.py", line 1475, in error
    self._log(ERROR, msg, args, **kwargs)
  File "/usr/lib/python3.8/logging/__init__.py", line 1589, in _log
    self.handle(record)
  File "/usr/lib/python3.8/logging/__init__.py", line 1599, in handle
    self.callHandlers(record)
  File "/usr/lib/python3.8/logging/__init__.py", line 1661, in callHandlers
    hdlr.handle(record)
  File "/usr/lib/python3.8/logging/__init__.py", line 954, in handle
    self.emit(record)
  File "/usr/lib/python3.8/logging/__init__.py", line 1093, in emit
    self.handleError(record)
  File "/usr/lib/python3.8/logging/__init__.py", line 1007, in handleError
    traceback.print_exception(t, v, tb, None, sys.stderr)
  File "/usr/lib/python3.8/traceback.py", line 103, in print_exception
    for line in TracebackException(
  File "/usr/lib/python3.8/traceback.py", line 508, in __init__
    self.stack = StackSummary.extract(
  File "/usr/lib/python3.8/traceback.py", line 366, in extract
    f.line
  File "/usr/lib/python3.8/traceback.py", line 288, in line
    self._line = linecache.getline(self.filename, self.lineno).strip()
  File "/usr/lib/python3.8/linecache.py", line 16, in getline
    lines = getlines(filename, module_globals)
  File "/usr/lib/python3.8/linecache.py", line 47, in getlines
    return updatecache(filename, module_globals)
  File "/usr/lib/python3.8/linecache.py", line 136, in updatecache
    with tokenize.open(fullname) as fp:
  File "/usr/lib/python3.8/tokenize.py", line 394, in open
    encoding, lines = detect_encoding(buffer.readline)
  File "/usr/lib/python3.8/tokenize.py", line 363, in detect_encoding
    first = read_or_stop()
  File "/usr/lib/python3.8/tokenize.py", line 321, in read_or_stop
    return readline()
  File "/home/basil/web-dev-2023/lab5/ve/lib/python3.8/site-packages/gunicorn/arbiter.py", line 242, in handle_chld
    self.reap_workers()
  File "/home/basil/web-dev-2023/lab5/ve/lib/python3.8/site-packages/gunicorn/arbiter.py", line 554, in reap_workers
    self.log.error(msg)
  File "/home/basil/web-dev-2023/lab5/ve/lib/python3.8/site-packages/gunicorn/glogging.py", line 272, in error
    self.error_log.error(msg, *args, **kwargs)
Message: 'Worker (pid:3639) was sent SIGHUP!'
Arguments: ()
Traceback (most recent call last):
  File "/usr/lib/python3.8/logging/__init__.py", line 1089, in emit
    self.flush()
  File "/usr/lib/python3.8/logging/__init__.py", line 1069, in flush
    self.stream.flush()
RuntimeError: reentrant call inside <_io.BufferedWriter name='<stderr>'>
Call stack:
  File "/home/basil/web-dev-2023/lab5/ve/bin/gunicorn", line 8, in <module>
    sys.exit(run())
  File "/home/basil/web-dev-2023/lab5/ve/lib/python3.8/site-packages/gunicorn/app/wsgiapp.py", line 67, in run
    WSGIApplication("%(prog)s [OPTIONS] [APP_MODULE]").run()
  File "/home/basil/web-dev-2023/lab5/ve/lib/python3.8/site-packages/gunicorn/app/base.py", line 236, in run
    super().run()
  File "/home/basil/web-dev-2023/lab5/ve/lib/python3.8/site-packages/gunicorn/app/base.py", line 72, in run
    Arbiter(self).run()
  File "/home/basil/web-dev-2023/lab5/ve/lib/python3.8/site-packages/gunicorn/arbiter.py", line 209, in run
    self.sleep()
  File "/home/basil/web-dev-2023/lab5/ve/lib/python3.8/site-packages/gunicorn/arbiter.py", line 360, in sleep
    ready = select.select([self.PIPE[0]], [], [], 1.0)
  File "/home/basil/web-dev-2023/lab5/ve/lib/python3.8/site-packages/gunicorn/arbiter.py", line 242, in handle_chld
    self.reap_workers()
  File "/home/basil/web-dev-2023/lab5/ve/lib/python3.8/site-packages/gunicorn/arbiter.py", line 554, in reap_workers
    self.log.error(msg)
  File "/home/basil/web-dev-2023/lab5/ve/lib/python3.8/site-packages/gunicorn/glogging.py", line 272, in error
    self.error_log.error(msg, *args, **kwargs)
  File "/usr/lib/python3.8/logging/__init__.py", line 1475, in error
    self._log(ERROR, msg, args, **kwargs)
  File "/usr/lib/python3.8/logging/__init__.py", line 1589, in _log
    self.handle(record)
  File "/usr/lib/python3.8/logging/__init__.py", line 1599, in handle
    self.callHandlers(record)
  File "/usr/lib/python3.8/logging/__init__.py", line 1661, in callHandlers
    hdlr.handle(record)
  File "/usr/lib/python3.8/logging/__init__.py", line 954, in handle
    self.emit(record)
  File "/usr/lib/python3.8/logging/__init__.py", line 1089, in emit
    self.flush()
  File "/usr/lib/python3.8/logging/__init__.py", line 1069, in flush
    self.stream.flush()
  File "/home/basil/web-dev-2023/lab5/ve/lib/python3.8/site-packages/gunicorn/arbiter.py", line 242, in handle_chld
    self.reap_workers()
  File "/home/basil/web-dev-2023/lab5/ve/lib/python3.8/site-packages/gunicorn/arbiter.py", line 554, in reap_workers
    self.log.error(msg)
  File "/home/basil/web-dev-2023/lab5/ve/lib/python3.8/site-packages/gunicorn/glogging.py", line 272, in error
    self.error_log.error(msg, *args, **kwargs)
Message: 'Worker (pid:3637) was sent SIGHUP!'
Arguments: ()
[2023-11-20 09:38:46 +0000] [17285] [INFO] Booting worker with pid: 17285
--- Logging error ---
Traceback (most recent call last):
  File "/usr/lib/python3.8/logging/__init__.py", line 1089, in emit
    self.flush()
  File "/usr/lib/python3.8/logging/__init__.py", line 1069, in flush
    self.stream.flush()
RuntimeError: reentrant call inside <_io.BufferedWriter name='<stderr>'>

During handling of the above exception, another exception occurred:

Traceback (most recent call last):
  File "/usr/lib/python3.8/logging/__init__.py", line 1089, in emit
    self.flush()
  File "/usr/lib/python3.8/logging/__init__.py", line 1069, in flush
    self.stream.flush()
RuntimeError: reentrant call inside <_io.BufferedWriter name='<stderr>'>
Call stack:
  File "/home/basil/web-dev-2023/lab5/ve/bin/gunicorn", line 8, in <module>
    sys.exit(run())
  File "/home/basil/web-dev-2023/lab5/ve/lib/python3.8/site-packages/gunicorn/app/wsgiapp.py", line 67, in run
    WSGIApplication("%(prog)s [OPTIONS] [APP_MODULE]").run()
  File "/home/basil/web-dev-2023/lab5/ve/lib/python3.8/site-packages/gunicorn/app/base.py", line 236, in run
    super().run()
  File "/home/basil/web-dev-2023/lab5/ve/lib/python3.8/site-packages/gunicorn/app/base.py", line 72, in run
    Arbiter(self).run()
  File "/home/basil/web-dev-2023/lab5/ve/lib/python3.8/site-packages/gunicorn/arbiter.py", line 209, in run
    self.sleep()
  File "/home/basil/web-dev-2023/lab5/ve/lib/python3.8/site-packages/gunicorn/arbiter.py", line 360, in sleep
    ready = select.select([self.PIPE[0]], [], [], 1.0)
  File "/home/basil/web-dev-2023/lab5/ve/lib/python3.8/site-packages/gunicorn/arbiter.py", line 242, in handle_chld
    self.reap_workers()
  File "/home/basil/web-dev-2023/lab5/ve/lib/python3.8/site-packages/gunicorn/arbiter.py", line 554, in reap_workers
    self.log.error(msg)
  File "/home/basil/web-dev-2023/lab5/ve/lib/python3.8/site-packages/gunicorn/glogging.py", line 272, in error
    self.error_log.error(msg, *args, **kwargs)
  File "/usr/lib/python3.8/logging/__init__.py", line 1475, in error
    self._log(ERROR, msg, args, **kwargs)
  File "/usr/lib/python3.8/logging/__init__.py", line 1589, in _log
    self.handle(record)
  File "/usr/lib/python3.8/logging/__init__.py", line 1599, in handle
    self.callHandlers(record)
  File "/usr/lib/python3.8/logging/__init__.py", line 1661, in callHandlers
    hdlr.handle(record)
  File "/usr/lib/python3.8/logging/__init__.py", line 954, in handle
    self.emit(record)
  File "/usr/lib/python3.8/logging/__init__.py", line 1089, in emit
    self.flush()
  File "/usr/lib/python3.8/logging/__init__.py", line 1069, in flush
    self.stream.flush()
  File "/home/basil/web-dev-2023/lab5/ve/lib/python3.8/site-packages/gunicorn/arbiter.py", line 242, in handle_chld
    self.reap_workers()
  File "/home/basil/web-dev-2023/lab5/ve/lib/python3.8/site-packages/gunicorn/arbiter.py", line 554, in reap_workers
    self.log.error(msg)
  File "/home/basil/web-dev-2023/lab5/ve/lib/python3.8/site-packages/gunicorn/glogging.py", line 272, in error
    self.error_log.error(msg, *args, **kwargs)
  File "/usr/lib/python3.8/logging/__init__.py", line 1475, in error
    self._log(ERROR, msg, args, **kwargs)
  File "/usr/lib/python3.8/logging/__init__.py", line 1589, in _log
    self.handle(record)
  File "/usr/lib/python3.8/logging/__init__.py", line 1599, in handle
    self.callHandlers(record)
  File "/usr/lib/python3.8/logging/__init__.py", line 1661, in callHandlers
    hdlr.handle(record)
  File "/usr/lib/python3.8/logging/__init__.py", line 954, in handle
    self.emit(record)
  File "/usr/lib/python3.8/logging/__init__.py", line 1093, in emit
    self.handleError(record)
  File "/usr/lib/python3.8/logging/__init__.py", line 1007, in handleError
    traceback.print_exception(t, v, tb, None, sys.stderr)
  File "/usr/lib/python3.8/traceback.py", line 103, in print_exception
    for line in TracebackException(
  File "/usr/lib/python3.8/traceback.py", line 508, in __init__
    self.stack = StackSummary.extract(
  File "/usr/lib/python3.8/traceback.py", line 366, in extract
    f.line
  File "/usr/lib/python3.8/traceback.py", line 288, in line
    self._line = linecache.getline(self.filename, self.lineno).strip()
  File "/usr/lib/python3.8/linecache.py", line 16, in getline
    lines = getlines(filename, module_globals)
  File "/usr/lib/python3.8/linecache.py", line 47, in getlines
    return updatecache(filename, module_globals)
  File "/usr/lib/python3.8/linecache.py", line 136, in updatecache
    with tokenize.open(fullname) as fp:
  File "/usr/lib/python3.8/tokenize.py", line 394, in open
    encoding, lines = detect_encoding(buffer.readline)
  File "/usr/lib/python3.8/tokenize.py", line 363, in detect_encoding
    first = read_or_stop()
  File "/usr/lib/python3.8/tokenize.py", line 321, in read_or_stop
    return readline()
  File "/home/basil/web-dev-2023/lab5/ve/lib/python3.8/site-packages/gunicorn/arbiter.py", line 242, in handle_chld
    self.reap_workers()
  File "/home/basil/web-dev-2023/lab5/ve/lib/python3.8/site-packages/gunicorn/arbiter.py", line 554, in reap_workers
    self.log.error(msg)
  File "/home/basil/web-dev-2023/lab5/ve/lib/python3.8/site-packages/gunicorn/glogging.py", line 272, in error
    self.error_log.error(msg, *args, **kwargs)
Message: 'Worker (pid:3639) was sent SIGHUP!'
Arguments: ()
Traceback (most recent call last):
  File "/usr/lib/python3.8/logging/__init__.py", line 1089, in emit
    self.flush()
  File "/usr/lib/python3.8/logging/__init__.py", line 1069, in flush
    self.stream.flush()
RuntimeError: reentrant call inside <_io.BufferedWriter name='<stderr>'>
Call stack:
  File "/home/basil/web-dev-2023/lab5/ve/bin/gunicorn", line 8, in <module>
    sys.exit(run())
  File "/home/basil/web-dev-2023/lab5/ve/lib/python3.8/site-packages/gunicorn/app/wsgiapp.py", line 67, in run
    WSGIApplication("%(prog)s [OPTIONS] [APP_MODULE]").run()
  File "/home/basil/web-dev-2023/lab5/ve/lib/python3.8/site-packages/gunicorn/app/base.py", line 236, in run
    super().run()
  File "/home/basil/web-dev-2023/lab5/ve/lib/python3.8/site-packages/gunicorn/app/base.py", line 72, in run
    Arbiter(self).run()
  File "/home/basil/web-dev-2023/lab5/ve/lib/python3.8/site-packages/gunicorn/arbiter.py", line 209, in run
    self.sleep()
  File "/home/basil/web-dev-2023/lab5/ve/lib/python3.8/site-packages/gunicorn/arbiter.py", line 360, in sleep
    ready = select.select([self.PIPE[0]], [], [], 1.0)
  File "/home/basil/web-dev-2023/lab5/ve/lib/python3.8/site-packages/gunicorn/arbiter.py", line 242, in handle_chld
    self.reap_workers()
  File "/home/basil/web-dev-2023/lab5/ve/lib/python3.8/site-packages/gunicorn/arbiter.py", line 554, in reap_workers
    self.log.error(msg)
  File "/home/basil/web-dev-2023/lab5/ve/lib/python3.8/site-packages/gunicorn/glogging.py", line 272, in error
    self.error_log.error(msg, *args, **kwargs)
  File "/usr/lib/python3.8/logging/__init__.py", line 1475, in error
    self._log(ERROR, msg, args, **kwargs)
  File "/usr/lib/python3.8/logging/__init__.py", line 1589, in _log
    self.handle(record)
  File "/usr/lib/python3.8/logging/__init__.py", line 1599, in handle
    self.callHandlers(record)
  File "/usr/lib/python3.8/logging/__init__.py", line 1661, in callHandlers
    hdlr.handle(record)
  File "/usr/lib/python3.8/logging/__init__.py", line 954, in handle
    self.emit(record)
  File "/usr/lib/python3.8/logging/__init__.py", line 1089, in emit
    self.flush()
  File "/usr/lib/python3.8/logging/__init__.py", line 1069, in flush
    self.stream.flush()
  File "/home/basil/web-dev-2023/lab5/ve/lib/python3.8/site-packages/gunicorn/arbiter.py", line 242, in handle_chld
    self.reap_workers()
  File "/home/basil/web-dev-2023/lab5/ve/lib/python3.8/site-packages/gunicorn/arbiter.py", line 554, in reap_workers
    self.log.error(msg)
  File "/home/basil/web-dev-2023/lab5/ve/lib/python3.8/site-packages/gunicorn/glogging.py", line 272, in error
    self.error_log.error(msg, *args, **kwargs)
Message: 'Worker (pid:3637) was sent SIGHUP!'
Arguments: ()
[2023-11-20 09:38:46 +0000] [17286] [INFO] Booting worker with pid: 17286
--- Logging error ---
Traceback (most recent call last):
  File "/usr/lib/python3.8/logging/__init__.py", line 1089, in emit
    self.flush()
  File "/usr/lib/python3.8/logging/__init__.py", line 1069, in flush
    self.stream.flush()
RuntimeError: reentrant call inside <_io.BufferedWriter name='<stderr>'>

During handling of the above exception, another exception occurred:

Traceback (most recent call last):
  File "/usr/lib/python3.8/logging/__init__.py", line 1089, in emit
    self.flush()
  File "/usr/lib/python3.8/logging/__init__.py", line 1069, in flush
    self.stream.flush()
RuntimeError: reentrant call inside <_io.BufferedWriter name='<stderr>'>
Call stack:
  File "/home/basil/web-dev-2023/lab5/ve/bin/gunicorn", line 8, in <module>
    sys.exit(run())
  File "/home/basil/web-dev-2023/lab5/ve/lib/python3.8/site-packages/gunicorn/app/wsgiapp.py", line 67, in run
    WSGIApplication("%(prog)s [OPTIONS] [APP_MODULE]").run()
  File "/home/basil/web-dev-2023/lab5/ve/lib/python3.8/site-packages/gunicorn/app/base.py", line 236, in run
    super().run()
  File "/home/basil/web-dev-2023/lab5/ve/lib/python3.8/site-packages/gunicorn/app/base.py", line 72, in run
    Arbiter(self).run()
  File "/home/basil/web-dev-2023/lab5/ve/lib/python3.8/site-packages/gunicorn/arbiter.py", line 209, in run
    self.sleep()
  File "/home/basil/web-dev-2023/lab5/ve/lib/python3.8/site-packages/gunicorn/arbiter.py", line 360, in sleep
    ready = select.select([self.PIPE[0]], [], [], 1.0)
  File "/home/basil/web-dev-2023/lab5/ve/lib/python3.8/site-packages/gunicorn/arbiter.py", line 242, in handle_chld
    self.reap_workers()
  File "/home/basil/web-dev-2023/lab5/ve/lib/python3.8/site-packages/gunicorn/arbiter.py", line 554, in reap_workers
    self.log.error(msg)
  File "/home/basil/web-dev-2023/lab5/ve/lib/python3.8/site-packages/gunicorn/glogging.py", line 272, in error
    self.error_log.error(msg, *args, **kwargs)
  File "/usr/lib/python3.8/logging/__init__.py", line 1475, in error
    self._log(ERROR, msg, args, **kwargs)
  File "/usr/lib/python3.8/logging/__init__.py", line 1589, in _log
    self.handle(record)
  File "/usr/lib/python3.8/logging/__init__.py", line 1599, in handle
    self.callHandlers(record)
  File "/usr/lib/python3.8/logging/__init__.py", line 1661, in callHandlers
    hdlr.handle(record)
  File "/usr/lib/python3.8/logging/__init__.py", line 954, in handle
    self.emit(record)
  File "/usr/lib/python3.8/logging/__init__.py", line 1089, in emit
    self.flush()
  File "/usr/lib/python3.8/logging/__init__.py", line 1069, in flush
    self.stream.flush()
  File "/home/basil/web-dev-2023/lab5/ve/lib/python3.8/site-packages/gunicorn/arbiter.py", line 242, in handle_chld
    self.reap_workers()
  File "/home/basil/web-dev-2023/lab5/ve/lib/python3.8/site-packages/gunicorn/arbiter.py", line 554, in reap_workers
    self.log.error(msg)
  File "/home/basil/web-dev-2023/lab5/ve/lib/python3.8/site-packages/gunicorn/glogging.py", line 272, in error
    self.error_log.error(msg, *args, **kwargs)
  File "/usr/lib/python3.8/logging/__init__.py", line 1475, in error
    self._log(ERROR, msg, args, **kwargs)
  File "/usr/lib/python3.8/logging/__init__.py", line 1589, in _log
    self.handle(record)
  File "/usr/lib/python3.8/logging/__init__.py", line 1599, in handle
    self.callHandlers(record)
  File "/usr/lib/python3.8/logging/__init__.py", line 1661, in callHandlers
    hdlr.handle(record)
  File "/usr/lib/python3.8/logging/__init__.py", line 954, in handle
    self.emit(record)
  File "/usr/lib/python3.8/logging/__init__.py", line 1093, in emit
    self.handleError(record)
  File "/usr/lib/python3.8/logging/__init__.py", line 1007, in handleError
    traceback.print_exception(t, v, tb, None, sys.stderr)
  File "/usr/lib/python3.8/traceback.py", line 103, in print_exception
    for line in TracebackException(
  File "/usr/lib/python3.8/traceback.py", line 508, in __init__
    self.stack = StackSummary.extract(
  File "/usr/lib/python3.8/traceback.py", line 366, in extract
    f.line
  File "/usr/lib/python3.8/traceback.py", line 288, in line
    self._line = linecache.getline(self.filename, self.lineno).strip()
  File "/usr/lib/python3.8/linecache.py", line 16, in getline
    lines = getlines(filename, module_globals)
  File "/usr/lib/python3.8/linecache.py", line 47, in getlines
    return updatecache(filename, module_globals)
  File "/usr/lib/python3.8/linecache.py", line 136, in updatecache
    with tokenize.open(fullname) as fp:
  File "/usr/lib/python3.8/tokenize.py", line 394, in open
    encoding, lines = detect_encoding(buffer.readline)
  File "/usr/lib/python3.8/tokenize.py", line 363, in detect_encoding
    first = read_or_stop()
  File "/usr/lib/python3.8/tokenize.py", line 321, in read_or_stop
    return readline()
  File "/home/basil/web-dev-2023/lab5/ve/lib/python3.8/site-packages/gunicorn/arbiter.py", line 242, in handle_chld
    self.reap_workers()
  File "/home/basil/web-dev-2023/lab5/ve/lib/python3.8/site-packages/gunicorn/arbiter.py", line 554, in reap_workers
    self.log.error(msg)
  File "/home/basil/web-dev-2023/lab5/ve/lib/python3.8/site-packages/gunicorn/glogging.py", line 272, in error
    self.error_log.error(msg, *args, **kwargs)
Message: 'Worker (pid:3639) was sent SIGHUP!'
Arguments: ()
Traceback (most recent call last):
  File "/usr/lib/python3.8/logging/__init__.py", line 1089, in emit
    self.flush()
  File "/usr/lib/python3.8/logging/__init__.py", line 1069, in flush
    self.stream.flush()
RuntimeError: reentrant call inside <_io.BufferedWriter name='<stderr>'>
Call stack:
  File "/home/basil/web-dev-2023/lab5/ve/bin/gunicorn", line 8, in <module>
    sys.exit(run())
  File "/home/basil/web-dev-2023/lab5/ve/lib/python3.8/site-packages/gunicorn/app/wsgiapp.py", line 67, in run
    WSGIApplication("%(prog)s [OPTIONS] [APP_MODULE]").run()
  File "/home/basil/web-dev-2023/lab5/ve/lib/python3.8/site-packages/gunicorn/app/base.py", line 236, in run
    super().run()
  File "/home/basil/web-dev-2023/lab5/ve/lib/python3.8/site-packages/gunicorn/app/base.py", line 72, in run
    Arbiter(self).run()
  File "/home/basil/web-dev-2023/lab5/ve/lib/python3.8/site-packages/gunicorn/arbiter.py", line 209, in run
    self.sleep()
  File "/home/basil/web-dev-2023/lab5/ve/lib/python3.8/site-packages/gunicorn/arbiter.py", line 360, in sleep
    ready = select.select([self.PIPE[0]], [], [], 1.0)
  File "/home/basil/web-dev-2023/lab5/ve/lib/python3.8/site-packages/gunicorn/arbiter.py", line 242, in handle_chld
    self.reap_workers()
  File "/home/basil/web-dev-2023/lab5/ve/lib/python3.8/site-packages/gunicorn/arbiter.py", line 554, in reap_workers
    self.log.error(msg)
  File "/home/basil/web-dev-2023/lab5/ve/lib/python3.8/site-packages/gunicorn/glogging.py", line 272, in error
    self.error_log.error(msg, *args, **kwargs)
  File "/usr/lib/python3.8/logging/__init__.py", line 1475, in error
    self._log(ERROR, msg, args, **kwargs)
  File "/usr/lib/python3.8/logging/__init__.py", line 1589, in _log
    self.handle(record)
  File "/usr/lib/python3.8/logging/__init__.py", line 1599, in handle
    self.callHandlers(record)
  File "/usr/lib/python3.8/logging/__init__.py", line 1661, in callHandlers
    hdlr.handle(record)
  File "/usr/lib/python3.8/logging/__init__.py", line 954, in handle
    self.emit(record)
  File "/usr/lib/python3.8/logging/__init__.py", line 1089, in emit
    self.flush()
  File "/usr/lib/python3.8/logging/__init__.py", line 1069, in flush
    self.stream.flush()
  File "/home/basil/web-dev-2023/lab5/ve/lib/python3.8/site-packages/gunicorn/arbiter.py", line 242, in handle_chld
    self.reap_workers()
  File "/home/basil/web-dev-2023/lab5/ve/lib/python3.8/site-packages/gunicorn/arbiter.py", line 554, in reap_workers
    self.log.error(msg)
  File "/home/basil/web-dev-2023/lab5/ve/lib/python3.8/site-packages/gunicorn/glogging.py", line 272, in error
    self.error_log.error(msg, *args, **kwargs)
Message: 'Worker (pid:3637) was sent SIGHUP!'
Arguments: ()
[2023-11-20 09:38:46 +0000] [17287] [INFO] Booting worker with pid: 17287
--- Logging error ---
Traceback (most recent call last):
  File "/usr/lib/python3.8/logging/__init__.py", line 1089, in emit
    self.flush()
  File "/usr/lib/python3.8/logging/__init__.py", line 1069, in flush
    self.stream.flush()
RuntimeError: reentrant call inside <_io.BufferedWriter name='<stderr>'>

During handling of the above exception, another exception occurred:

Traceback (most recent call last):
  File "/usr/lib/python3.8/logging/__init__.py", line 1089, in emit
    self.flush()
  File "/usr/lib/python3.8/logging/__init__.py", line 1069, in flush
    self.stream.flush()
RuntimeError: reentrant call inside <_io.BufferedWriter name='<stderr>'>
Call stack:
  File "/home/basil/web-dev-2023/lab5/ve/bin/gunicorn", line 8, in <module>
    sys.exit(run())
  File "/home/basil/web-dev-2023/lab5/ve/lib/python3.8/site-packages/gunicorn/app/wsgiapp.py", line 67, in run
    WSGIApplication("%(prog)s [OPTIONS] [APP_MODULE]").run()
  File "/home/basil/web-dev-2023/lab5/ve/lib/python3.8/site-packages/gunicorn/app/base.py", line 236, in run
    super().run()
  File "/home/basil/web-dev-2023/lab5/ve/lib/python3.8/site-packages/gunicorn/app/base.py", line 72, in run
    Arbiter(self).run()
  File "/home/basil/web-dev-2023/lab5/ve/lib/python3.8/site-packages/gunicorn/arbiter.py", line 209, in run
    self.sleep()
  File "/home/basil/web-dev-2023/lab5/ve/lib/python3.8/site-packages/gunicorn/arbiter.py", line 360, in sleep
    ready = select.select([self.PIPE[0]], [], [], 1.0)
  File "/home/basil/web-dev-2023/lab5/ve/lib/python3.8/site-packages/gunicorn/arbiter.py", line 242, in handle_chld
    self.reap_workers()
  File "/home/basil/web-dev-2023/lab5/ve/lib/python3.8/site-packages/gunicorn/arbiter.py", line 554, in reap_workers
    self.log.error(msg)
  File "/home/basil/web-dev-2023/lab5/ve/lib/python3.8/site-packages/gunicorn/glogging.py", line 272, in error
    self.error_log.error(msg, *args, **kwargs)
  File "/usr/lib/python3.8/logging/__init__.py", line 1475, in error
    self._log(ERROR, msg, args, **kwargs)
  File "/usr/lib/python3.8/logging/__init__.py", line 1589, in _log
    self.handle(record)
  File "/usr/lib/python3.8/logging/__init__.py", line 1599, in handle
    self.callHandlers(record)
  File "/usr/lib/python3.8/logging/__init__.py", line 1661, in callHandlers
    hdlr.handle(record)
  File "/usr/lib/python3.8/logging/__init__.py", line 954, in handle
    self.emit(record)
  File "/usr/lib/python3.8/logging/__init__.py", line 1089, in emit
    self.flush()
  File "/usr/lib/python3.8/logging/__init__.py", line 1069, in flush
    self.stream.flush()
  File "/home/basil/web-dev-2023/lab5/ve/lib/python3.8/site-packages/gunicorn/arbiter.py", line 242, in handle_chld
    self.reap_workers()
  File "/home/basil/web-dev-2023/lab5/ve/lib/python3.8/site-packages/gunicorn/arbiter.py", line 554, in reap_workers
    self.log.error(msg)
  File "/home/basil/web-dev-2023/lab5/ve/lib/python3.8/site-packages/gunicorn/glogging.py", line 272, in error
    self.error_log.error(msg, *args, **kwargs)
  File "/usr/lib/python3.8/logging/__init__.py", line 1475, in error
    self._log(ERROR, msg, args, **kwargs)
  File "/usr/lib/python3.8/logging/__init__.py", line 1589, in _log
    self.handle(record)
  File "/usr/lib/python3.8/logging/__init__.py", line 1599, in handle
    self.callHandlers(record)
  File "/usr/lib/python3.8/logging/__init__.py", line 1661, in callHandlers
    hdlr.handle(record)
  File "/usr/lib/python3.8/logging/__init__.py", line 954, in handle
    self.emit(record)
  File "/usr/lib/python3.8/logging/__init__.py", line 1093, in emit
    self.handleError(record)
  File "/usr/lib/python3.8/logging/__init__.py", line 1007, in handleError
    traceback.print_exception(t, v, tb, None, sys.stderr)
  File "/usr/lib/python3.8/traceback.py", line 103, in print_exception
    for line in TracebackException(
  File "/usr/lib/python3.8/traceback.py", line 508, in __init__
    self.stack = StackSummary.extract(
  File "/usr/lib/python3.8/traceback.py", line 366, in extract
    f.line
  File "/usr/lib/python3.8/traceback.py", line 288, in line
    self._line = linecache.getline(self.filename, self.lineno).strip()
  File "/usr/lib/python3.8/linecache.py", line 16, in getline
    lines = getlines(filename, module_globals)
  File "/usr/lib/python3.8/linecache.py", line 47, in getlines
    return updatecache(filename, module_globals)
  File "/usr/lib/python3.8/linecache.py", line 136, in updatecache
    with tokenize.open(fullname) as fp:
  File "/usr/lib/python3.8/tokenize.py", line 394, in open
    encoding, lines = detect_encoding(buffer.readline)
  File "/usr/lib/python3.8/tokenize.py", line 363, in detect_encoding
    first = read_or_stop()
  File "/usr/lib/python3.8/tokenize.py", line 321, in read_or_stop
    return readline()
  File "/home/basil/web-dev-2023/lab5/ve/lib/python3.8/site-packages/gunicorn/arbiter.py", line 242, in handle_chld
    self.reap_workers()
  File "/home/basil/web-dev-2023/lab5/ve/lib/python3.8/site-packages/gunicorn/arbiter.py", line 554, in reap_workers
    self.log.error(msg)
  File "/home/basil/web-dev-2023/lab5/ve/lib/python3.8/site-packages/gunicorn/glogging.py", line 272, in error
    self.error_log.error(msg, *args, **kwargs)
Message: 'Worker (pid:3639) was sent SIGHUP!'
Arguments: ()
Traceback (most recent call last):
  File "/usr/lib/python3.8/logging/__init__.py", line 1089, in emit
    self.flush()
  File "/usr/lib/python3.8/logging/__init__.py", line 1069, in flush
    self.stream.flush()
RuntimeError: reentrant call inside <_io.BufferedWriter name='<stderr>'>
Call stack:
  File "/home/basil/web-dev-2023/lab5/ve/bin/gunicorn", line 8, in <module>
    sys.exit(run())
  File "/home/basil/web-dev-2023/lab5/ve/lib/python3.8/site-packages/gunicorn/app/wsgiapp.py", line 67, in run
    WSGIApplication("%(prog)s [OPTIONS] [APP_MODULE]").run()
  File "/home/basil/web-dev-2023/lab5/ve/lib/python3.8/site-packages/gunicorn/app/base.py", line 236, in run
    super().run()
  File "/home/basil/web-dev-2023/lab5/ve/lib/python3.8/site-packages/gunicorn/app/base.py", line 72, in run
    Arbiter(self).run()
  File "/home/basil/web-dev-2023/lab5/ve/lib/python3.8/site-packages/gunicorn/arbiter.py", line 209, in run
    self.sleep()
  File "/home/basil/web-dev-2023/lab5/ve/lib/python3.8/site-packages/gunicorn/arbiter.py", line 360, in sleep
    ready = select.select([self.PIPE[0]], [], [], 1.0)
  File "/home/basil/web-dev-2023/lab5/ve/lib/python3.8/site-packages/gunicorn/arbiter.py", line 242, in handle_chld
    self.reap_workers()
  File "/home/basil/web-dev-2023/lab5/ve/lib/python3.8/site-packages/gunicorn/arbiter.py", line 554, in reap_workers
    self.log.error(msg)
  File "/home/basil/web-dev-2023/lab5/ve/lib/python3.8/site-packages/gunicorn/glogging.py", line 272, in error
    self.error_log.error(msg, *args, **kwargs)
  File "/usr/lib/python3.8/logging/__init__.py", line 1475, in error
    self._log(ERROR, msg, args, **kwargs)
  File "/usr/lib/python3.8/logging/__init__.py", line 1589, in _log
    self.handle(record)
  File "/usr/lib/python3.8/logging/__init__.py", line 1599, in handle
    self.callHandlers(record)
  File "/usr/lib/python3.8/logging/__init__.py", line 1661, in callHandlers
    hdlr.handle(record)
  File "/usr/lib/python3.8/logging/__init__.py", line 954, in handle
    self.emit(record)
  File "/usr/lib/python3.8/logging/__init__.py", line 1089, in emit
    self.flush()
  File "/usr/lib/python3.8/logging/__init__.py", line 1069, in flush
    self.stream.flush()
  File "/home/basil/web-dev-2023/lab5/ve/lib/python3.8/site-packages/gunicorn/arbiter.py", line 242, in handle_chld
    self.reap_workers()
  File "/home/basil/web-dev-2023/lab5/ve/lib/python3.8/site-packages/gunicorn/arbiter.py", line 554, in reap_workers
    self.log.error(msg)
  File "/home/basil/web-dev-2023/lab5/ve/lib/python3.8/site-packages/gunicorn/glogging.py", line 272, in error
    self.error_log.error(msg, *args, **kwargs)
Message: 'Worker (pid:3637) was sent SIGHUP!'
Arguments: ()
[2023-11-20 09:38:46 +0000] [3618] [INFO] Handling signal: hup
[2023-11-20 09:38:46 +0000] [3618] [INFO] Hang up: Master
[2023-11-20 09:38:46 +0000] [17266] [INFO] Worker exiting (pid: 17266)
[2023-11-20 09:38:46 +0000] [17285] [INFO] Worker exiting (pid: 17285)
[2023-11-20 09:38:46 +0000] [17289] [INFO] Booting worker with pid: 17289
[2023-11-20 09:38:46 +0000] [17290] [INFO] Booting worker with pid: 17290
[2023-11-20 09:38:46 +0000] [17288] [INFO] Booting worker with pid: 17288
[2023-11-20 09:38:46 +0000] [17291] [INFO] Booting worker with pid: 17291
[2023-11-20 09:38:47 +0000] [3618] [ERROR] Worker (pid:17285) was sent SIGTERM!
[2023-11-20 09:38:47 +0000] [17286] [INFO] Worker exiting (pid: 17286)
[2023-11-20 09:38:47 +0000] [17287] [INFO] Worker exiting (pid: 17287)
